<?xml version="1.0" encoding="utf-8"?>
<!-- This URDF was automatically created by SolidWorks to URDF Exporter! Originally created by Stephen Brawner (brawner@gmail.com) 
     Commit Version: 1.6.0-4-g7f85cfe  Build Version: 1.6.7995.38578
     For more information, please see http://wiki.ros.org/sw_urdf_exporter -->
<robot
  name="cello_description">
      <!-- 添加虚拟根链接 -->
  <!-- <link name="world"/> -->

  <!-- 添加固定关节 -->
  <!-- <joint name="world_to_base" type="fixed">
    <parent link="world"/>
    <child link="base_link"/>
    <origin xyz="0 0 0" rpy="0 0 0"/>
  </joint> -->
  <link
    name="base_link">
    <inertial>
      <origin
        xyz="0.0185665958388107 -0.000316871998748433 0.0237703344106882"
        rpy="0 0 0" />
      <mass
        value="0.860146104031393" />
      <inertia
        ixx="0.00164232799354795"
        ixy="-1.59502029029472E-06"
        ixz="-6.71840185118193E-06"
        iyy="0.00170608787385062"
        iyz="2.52071113884237E-06"
        izz="0.00312628775870806" />
    </inertial>
    <visual>
      <origin
        xyz="0 0 0"
        rpy="0 0 0" />
      <geometry>
        <mesh
          filename="file://$(find cello_gazebo)/meshes/base_link.STL" />
      </geometry>
      <material
        name="">
        <color
          rgba="0.79216 0.81961 0.93333 1" />
      </material>
    </visual>
    <collision>
      <origin
        xyz="0 0 0"
        rpy="0 0 0" />
      <geometry>
        <mesh
          filename="file://$(find cello_gazebo)/meshes/base_link.STL" />
      </geometry>
    </collision>
  </link>
  <link
    name="link1">
    <inertial>
      <origin
        xyz="-0.00293659514385111 -0.000166267232103858 0.0304852649910811"
        rpy="0 0 0" />
      <mass
        value="0.211492634096808" />
      <inertia
        ixx="0.000143717201104042"
        ixy="3.66663819370481E-08"
        ixz="-1.62979838053402E-07"
        iyy="0.000130150440516505"
        iyz="2.18212572706699E-07"
        izz="0.000192189810713929" />
    </inertial>
    <visual>
      <origin
        xyz="0 0 0"
        rpy="0 0 0" />
      <geometry>
        <mesh
          filename="file://$(find cello_gazebo)/meshes/link1.STL" />
      </geometry>
      <material
        name="">
        <color
          rgba="0.792156862745098 0.819607843137255 0.933333333333333 1" />
      </material>
    </visual>
    <collision>
      <origin
        xyz="0 0 0"
        rpy="0 0 0" />
      <geometry>
        <mesh
          filename="file://$(find cello_gazebo)/meshes/link1.STL" />
      </geometry>
    </collision>
  </link>
  <joint
    name="joint1"
    type="revolute">
    <origin
      xyz="0 0 0.0665"
      rpy="0 0 3.14159265358979" />
    <parent
      link="base_link" />
    <child
      link="link1" />
    <axis
      xyz="0 0 -1" />
    <limit
      lower="-2.27"
      upper="2.27"
      effort="100"
      velocity="1" />
  </joint>
  <link
    name="link2">
    <inertial>
      <origin
        xyz="0.189226589136491 -0.0113695378685387 -1.64041947557948E-05"
        rpy="0 0 0" />
      <mass
        value="0.226428575789942" />
      <inertia
        ixx="9.22325814550601E-05"
        ixy="-3.0584420306772E-07"
        ixz="3.39116118211324E-08"
        iyy="0.00027560854211988"
        iyz="1.47692248125528E-07"
        izz="0.000266467551886924" />
    </inertial>
    <visual>
      <origin
        xyz="0 0 0"
        rpy="0 0 0" />
      <geometry>
        <mesh
          filename="file://$(find cello_gazebo)/meshes/link2.STL" />
      </geometry>
      <material
        name="">
        <color
          rgba="0.792156862745098 0.819607843137255 0.933333333333333 1" />
      </material>
    </visual>
    <collision>
      <origin
        xyz="0 0 0"
        rpy="0 0 0" />
      <geometry>
        <mesh
          filename="file://$(find cello_gazebo)/meshes/link2.STL" />
      </geometry>
    </collision>
  </link>
  <joint
    name="joint2"
    type="revolute">
    <origin
      xyz="0.0022 0 0.0638"
      rpy="1.5708 -1.5708 0" />
    <parent
      link="link1" />
    <child
      link="link2" />
    <axis
      xyz="0 0 -1" />
    <limit
      lower="-1.57"
      upper="1.57"
      effort="100"
      velocity="1" />
  </joint>
  <link
    name="link3">
    <inertial>
      <origin
        xyz="0.0611057027698938 -0.00285373563465841 -0.000308179387542537"
        rpy="0 0 0" />
      <mass
        value="0.0623016674269844" />
      <inertia
        ixx="3.27641771814371E-05"
        ixy="1.36991125224236E-07"
        ixz="5.03629347287245E-11"
        iyy="2.8138233772221E-05"
        iyz="-2.07089691930367E-12"
        izz="2.00711122359931E-05" />
    </inertial>
    <visual>
      <origin
        xyz="0 0 0"
        rpy="0 0 0" />
      <geometry>
        <mesh
          filename="file://$(find cello_gazebo)/meshes/link3.STL" />
      </geometry>
      <material
        name="">
        <color
          rgba="0.792156862745098 0.819607843137255 0.933333333333333 1" />
      </material>
    </visual>
    <collision>
      <origin
        xyz="0 0 0"
        rpy="0 0 0" />
      <geometry>
        <mesh
          filename="file://$(find cello_gazebo)/meshes/link3.STL" />
      </geometry>
    </collision>
  </link>
  <joint
    name="joint3"
    type="revolute">
    <origin
      xyz="0.2476 -0.0396 0"
      rpy="0 0 -1.5708" />
    <parent
      link="link2" />
    <child
      link="link3" />
    <axis
      xyz="0 0 -1" />
    <limit
      lower="-1.57"
      upper="1.57"
      effort="100"
      velocity="1" />
  </joint>
  <link
    name="link4">
    <inertial>
      <origin
        xyz="0.000745555247010754 -0.000138360041998193 -0.106220756274278"
        rpy="0 0 0" />
      <mass
        value="0.0831858188735885" />
      <inertia
        ixx="0.000102578634806798"
        ixy="3.36167527477372E-08"
        ixz="1.60143434133562E-07"
        iyy="9.27604150962016E-05"
        iyz="9.03345793295877E-09"
        izz="1.82817305345178E-05" />
    </inertial>
    <visual>
      <origin
        xyz="0 0 0"
        rpy="0 0 0" />
      <geometry>
        <mesh
          filename="file://$(find cello_gazebo)/meshes/link4.STL" />
      </geometry>
      <material
        name="">
        <color
          rgba="0.792156862745098 0.819607843137255 0.933333333333333 1" />
      </material>
    </visual>
    <collision>
      <origin
        xyz="0 0 0"
        rpy="0 0 0" />
      <geometry>
        <mesh
          filename="file://$(find cello_gazebo)/meshes/link4.STL" />
      </geometry>
    </collision>
  </link>
  <joint
    name="joint4"
    type="revolute">
    <origin
      xyz="0.26712 -0.00308 0"
      rpy="1.5708 0 1.5708" />
    <parent
      link="link3" />
    <child
      link="link4" />
    <axis
      xyz="0 0 -1" />
    <limit
      lower="-2.27"
      upper="2.27"
      effort="100"
      velocity="1" />
  </joint>
  <link
    name="link5">
    <inertial>
      <origin
        xyz="-0.00767914962421345 -0.030181521070214 -0.00029872886431521"
        rpy="0 0 0" />
      <mass
        value="0.0181852018389062" />
      <inertia
        ixx="4.56965782990531E-06"
        ixy="-6.95561752431801E-07"
        ixz="-2.59810714043586E-13"
        iyy="4.73221658107135E-06"
        iyz="-5.0896164968914E-11"
        izz="4.79023492543246E-06" />
    </inertial>
    <visual>
      <origin
        xyz="0 0 0"
        rpy="0 0 0" />
      <geometry>
        <mesh
          filename="file://$(find cello_gazebo)/meshes/link5.STL" />
      </geometry>
      <material
        name="">
        <color
          rgba="0.792156862745098 0.819607843137255 0.933333333333333 1" />
      </material>
    </visual>
    <collision>
      <origin
        xyz="0 0 0"
        rpy="0 0 0" />
      <geometry>
        <mesh
          filename="file://$(find cello_gazebo)/meshes/link5.STL" />
      </geometry>
    </collision>
  </link>
  <joint
    name="joint5"
    type="revolute">
    <origin
      xyz="0 0 0"
      rpy="-1.5708 0 0" />
    <parent
      link="link4" />
    <child
      link="link5" />
    <axis
      xyz="0 0 -1" />
    <limit
      lower="-1.57"
      upper="1.57"
      effort="100"
      velocity="1" />
  </joint>
  <link
    name="link6">
    <inertial>
      <origin
        xyz="-0.00032947502720399 0.00742369665426917 -0.0656755875584048"
        rpy="0 0 0" />
      <mass
        value="0.0539231941559604" />
      <inertia
        ixx="2.73524846835263E-05"
        ixy="-5.11378434619857E-08"
        ixz="-5.38863543981338E-08"
        iyy="8.14363187419384E-05"
        iyz="-3.75607498934119E-06"
        izz="7.03066761474059E-05" />
    </inertial>
    <visual>
      <origin
        xyz="0 0 0"
        rpy="0 0 0" />
      <geometry>
        <mesh
          filename="file://$(find cello_gazebo)/meshes/link6.STL" />
      </geometry>
      <material
        name="">
        <color
          rgba="0.792156862745098 0.819607843137255 0.933333333333333 1" />
      </material>
    </visual>
    <collision>
      <origin
        xyz="0 0 0"
        rpy="0 0 0" />
      <geometry>
        <mesh
          filename="file://$(find cello_gazebo)/meshes/link6.STL" />
      </geometry>
    </collision>
  </link>
  <joint
    name="joint6"
    type="revolute">
    <origin
      xyz="-0.001325 -0.17066 0"
      rpy="1.5708 -1.5708 0" />
    <parent
      link="link5" />
    <child
      link="link6" />
    <axis
      xyz="0 0 -1" />
    <limit
      lower="-2.27"
      upper="2.27"
      effort="100"
      velocity="1" />
  </joint>
  <link
    name="link7_left">
    <inertial>
      <origin
        xyz="4.33087985037273E-05 -0.0210288805335849 0.032103054040318"
        rpy="0 0 0" />
      <mass
        value="0.0118967398398553" />
      <inertia
        ixx="1.53554000943577E-06"
        ixy="-6.15488946521751E-11"
        ixz="1.07737509951946E-22"
        iyy="8.5835663413382E-07"
        iyz="2.09480277751459E-07"
        izz="1.93904913603243E-06" />
    </inertial>
    <visual>
      <origin
        xyz="0 0 0"
        rpy="0 0 0" />
      <geometry>
        <mesh
          filename="file://$(find cello_gazebo)/meshes/link7_left.STL" />
      </geometry>
      <material
        name="">
        <color
          rgba="0.792156862745098 0.819607843137255 0.933333333333333 1" />
      </material>
    </visual>
    <collision>
      <origin
        xyz="0 0 0"
        rpy="0 0 0" />
      <geometry>
        <mesh
          filename="file://$(find cello_gazebo)/meshes/link7_left.STL" />
      </geometry>
    </collision>
  </link>
  <joint
    name="joint7_left"
    type="prismatic">
    <origin
      xyz="0 0.013687 0"
      rpy="1.5708 0 -1.5708" />
    <parent
      link="link6" />
    <child
      link="link7_left" />
    <axis
      xyz="0 0 1" />
    <limit
      lower="-0.03"
      upper="0"
      effort="5"
      velocity="3.14" />
  </joint>
  <link
    name="link7_right">
    <inertial>
      <origin
        xyz="-4.33087985039493E-05 -0.0210288805335849 -0.0312030540403159"
        rpy="0 0 0" />
      <mass
        value="0.0118967398398553" />
      <inertia
        ixx="1.53554000943577E-06"
        ixy="6.15488946515659E-11"
        ixz="9.31744286009304E-23"
        iyy="8.58356634133819E-07"
        iyz="-2.09480277751459E-07"
        izz="1.93904913603243E-06" />
    </inertial>
    <visual>
      <origin
        xyz="0 0 0"
        rpy="0 0 0" />
      <geometry>
        <mesh
          filename="file://$(find cello_gazebo)/meshes/link7_right.STL" />
      </geometry>
      <material
        name="">
        <color
          rgba="0.792156862745098 0.819607843137255 0.933333333333333 1" />
      </material>
    </visual>
    <collision>
      <origin
        xyz="0 0 0"
        rpy="0 0 0" />
      <geometry>
        <mesh
          filename="file://$(find cello_gazebo)/meshes/link7_right.STL" />
      </geometry>
    </collision>
  </link>
  <joint
    name="joint7_right"
    type="prismatic">
    <origin
      xyz="0 0.013687 0"
      rpy="1.5708 0 -1.5708" />
    <parent
      link="link6" />
    <child
      link="link7_right" />
    <axis
      xyz="0 0 -1" />
    <limit
      lower="-3.14"
      upper="3.14"
      effort="5"
      velocity="3.14" />
    <mimic joint="joint7_left" />
  </joint>
</robot>