<?xml version="1.0" encoding="utf-8"?>
<!-- This URDF was automatically created by SolidWorks to URDF Exporter! Originally created by Stephen Brawner (brawner@gmail.com) 
     Commit Version: 1.6.0-4-g7f85cfe  Build Version: 1.6.7995.38578
     For more information, please see http://wiki.ros.org/sw_urdf_exporter -->
<robot
  name="stararm102_description">
      <!-- 添加虚拟根链接 -->
  <link name="world"/>

  <!-- 添加固定关节 -->
  <joint name="world_to_base" type="fixed">
    <parent link="world"/>
    <child link="base_link"/>
    <origin xyz="0 0 0" rpy="0 0 0"/>
  </joint>
  <link
    name="base_link">
    <inertial>
      <origin
        xyz="-0.0300632996335358 4.23029469302262E-06 0.0236059679332401"
        rpy="0 0 0" />
      <mass
        value="0.133140629988521" />
      <inertia
        ixx="9.75475153646954E-05"
        ixy="-5.70580611237351E-09"
        ixz="3.50145171357219E-06"
        iyy="7.63359480528202E-05"
        iyz="-8.67930496852705E-09"
        izz="9.48457088481919E-05" />
    </inertial>
    <visual>
      <origin
        xyz="0 0 0"
        rpy="0 0 0" />
      <geometry>
        <mesh
          filename="package://stararm102_description/meshes/base_link.STL" />
      </geometry>
      <material
        name="">
        <color
          rgba="1 1 1 1" />
      </material>
    </visual>
    <collision>
      <origin
        xyz="0 0 0"
        rpy="0 0 0" />
      <geometry>
        <mesh
          filename="package://stararm102_description/meshes/base_link.STL" />
      </geometry>
    </collision>
  </link>
  <link
    name="link1">
    <inertial>
      <origin
        xyz="0.0241278504598692 2.97078999306512E-05 0.0274468471158838"
        rpy="0 0 0" />
      <mass
        value="0.0490447462840961" />
      <inertia
        ixx="2.96403139602316E-05"
        ixy="-8.39151674795228E-10"
        ixz="-3.60040828150387E-06"
        iyy="2.95907005051813E-05"
        iyz="-8.33306207576828E-09"
        izz="1.26228781611057E-05" />
    </inertial>
    <visual>
      <origin
        xyz="0 0 0"
        rpy="0 0 0" />
      <geometry>
        <mesh
          filename="package://stararm102_description/meshes/link1.STL" />
      </geometry>
      <material
        name="">
        <color
          rgba="1 1 1 1" />
      </material>
    </visual>
    <collision>
      <origin
        xyz="0 0 0"
        rpy="0 0 0" />
      <geometry>
        <mesh
          filename="package://stararm102_description/meshes/link1.STL" />
      </geometry>
    </collision>
  </link>
  <joint
    name="joint1"
    type="revolute">
    <origin
      xyz="0 0 0.04475"
      rpy="0 0 0" />
    <parent
      link="base_link" />
    <child
      link="link1" />
    <axis
      xyz="0 0 -1" />
    <limit
      lower="-2.27"
      upper="2.27"
      effort="100"
      velocity="1" />
  </joint>
  <link
    name="link2">
    <inertial>
      <origin
        xyz="0.0729892507852211 -0.00160649145550098 -0.00019732369871768"
        rpy="0 0 0" />
      <mass
        value="0.0902416570859392" />
      <inertia
        ixx="4.19253099246556E-05"
        ixy="-2.25855581551639E-06"
        ixz="-4.44155834371899E-08"
        iyy="0.00015660712389644"
        iyz="-1.17494738458986E-08"
        izz="0.000125752449573264" />
    </inertial>
    <visual>
      <origin
        xyz="0 0 0"
        rpy="0 0 0" />
      <geometry>
        <mesh
          filename="package://stararm102_description/meshes/link2.STL" />
      </geometry>
      <material
        name="">
        <color
          rgba="1 1 1 1" />
      </material>
    </visual>
    <collision>
      <origin
        xyz="0 0 0"
        rpy="0 0 0" />
      <geometry>
        <mesh
          filename="package://stararm102_description/meshes/link2.STL" />
      </geometry>
    </collision>
  </link>
  <joint
    name="joint2"
    type="revolute">
    <origin
      xyz="0.02775 0 0.061925"
      rpy="1.5708 -1.5708 0" />
    <parent
      link="link1" />
    <child
      link="link2" />
    <axis
      xyz="0 0 -1" />
    <limit
      lower="-1.57"
      upper="1.57"
      effort="100"
      velocity="1" />
  </joint>
  <link
    name="link3">
    <inertial>
      <origin
        xyz="0.075237507815636 1.43180955125277E-05 -0.000199033367391119"
        rpy="0 0 0" />
      <mass
        value="0.092247950009267" />
      <inertia
        ixx="4.14780596161942E-05"
        ixy="1.53670997361533E-09"
        ixz="-2.04184589983835E-08"
        iyy="0.000152786299857704"
        iyz="-1.17528145438487E-09"
        izz="0.000120845855952267" />
    </inertial>
    <visual>
      <origin
        xyz="0 0 0"
        rpy="0 0 0" />
      <geometry>
        <mesh
          filename="package://stararm102_description/meshes/link3.STL" />
      </geometry>
      <material
        name="">
        <color
          rgba="1 1 1 1" />
      </material>
    </visual>
    <collision>
      <origin
        xyz="0 0 0"
        rpy="0 0 0" />
      <geometry>
        <mesh
          filename="package://stararm102_description/meshes/link3.STL" />
      </geometry>
    </collision>
  </link>
  <joint
    name="joint3"
    type="revolute">
    <origin
      xyz="0.11225 -0.026175 0"
      rpy="0 0 -1.5708" />
    <parent
      link="link2" />
    <child
      link="link3" />
    <axis
      xyz="0 0 -1" />
    <limit
      lower="-1.57"
      upper="1.57"
      effort="100"
      velocity="1" />
  </joint>
  <link
    name="link4">
    <inertial>
      <origin
        xyz="0.0196476212810571 -0.00122040006406537 -1.66728029773015E-05"
        rpy="0 0 0" />
      <mass
        value="0.0298155768600067" />
      <inertia
        ixx="1.13287289583413E-05"
        ixy="2.41907719305386E-08"
        ixz="7.43738348850089E-09"
        iyy="1.29843883333036E-05"
        iyz="5.45539379109613E-09"
        izz="5.59222447452988E-06" />
    </inertial>
    <visual>
      <origin
        xyz="0 0 0"
        rpy="0 0 0" />
      <geometry>
        <mesh
          filename="package://stararm102_description/meshes/link4.STL" />
      </geometry>
      <material
        name="">
        <color
          rgba="1 1 1 1" />
      </material>
    </visual>
    <collision>
      <origin
        xyz="0 0 0"
        rpy="0 0 0" />
      <geometry>
        <mesh
          filename="package://stararm102_description/meshes/link4.STL" />
      </geometry>
    </collision>
  </link>
  <joint
    name="joint4"
    type="revolute">
    <origin
      xyz="0.14117 0 0"
      rpy="0 0 0" />
    <parent
      link="link3" />
    <child
      link="link4" />
    <axis
      xyz="0 0 -1" />
    <limit
      lower="-1.57"
      upper="1.57"
      effort="100"
      velocity="1" />
  </joint>
  <link
    name="link5">
    <inertial>
      <origin
        xyz="0.0229686824522496 5.43222379498914E-07 0.0123129330887689"
        rpy="0 0 0" />
      <mass
        value="0.0455712723510246" />
      <inertia
        ixx="9.22596706562675E-06"
        ixy="-2.60094169039893E-12"
        ixz="4.23121647381554E-07"
        iyy="1.47418355948446E-05"
        iyz="1.59173410356726E-12"
        izz="1.33182922768924E-05" />
    </inertial>
    <visual>
      <origin
        xyz="0 0 0"
        rpy="0 0 0" />
      <geometry>
        <mesh
          filename="package://stararm102_description/meshes/link5.STL" />
      </geometry>
      <material
        name="">
        <color
          rgba="1 1 1 1" />
      </material>
    </visual>
    <collision>
      <origin
        xyz="0 0 0"
        rpy="0 0 0" />
      <geometry>
        <mesh
          filename="package://stararm102_description/meshes/link5.STL" />
      </geometry>
    </collision>
  </link>
  <joint
    name="joint5"
    type="revolute">
    <origin
      xyz="0.029 0 0"
      rpy="-1.5708 0 0" />
    <parent
      link="link4" />
    <child
      link="link5" />
    <axis
      xyz="0 0 -1" />
    <limit
      lower="-1.57"
      upper="1.57"
      effort="100"
      velocity="1" />
  </joint>
  <link
    name="link6">
    <inertial>
      <origin
        xyz="-0.00415459388524732 -6.87763721066437E-05 -0.0756167187403363"
        rpy="0 0 0" />
      <mass
        value="0.0277279216939168" />
      <inertia
        ixx="6.063125125658E-06"
        ixy="3.91296866902188E-08"
        ixz="1.0101601375488E-06"
        iyy="6.31326639534249E-06"
        iyz="-9.82075622763034E-09"
        izz="7.98591452521941E-06" />
    </inertial>
    <visual>
      <origin
        xyz="0 0 0"
        rpy="0 0 0" />
      <geometry>
        <mesh
          filename="package://stararm102_description/meshes/link6.STL" />
      </geometry>
      <material
        name="">
        <color
          rgba="1 1 1 1" />
      </material>
    </visual>
    <collision>
      <origin
        xyz="0 0 0"
        rpy="0 0 0" />
      <geometry>
        <mesh
          filename="package://stararm102_description/meshes/link6.STL" />
      </geometry>
    </collision>
  </link>
  <joint
    name="joint6"
    type="revolute">
    <origin
      xyz="0.14968 0 0.0038453"
      rpy="-1.5708 0 -1.5708" />
    <parent
      link="link5" />
    <child
      link="link6" />
    <axis
      xyz="0 0 -1" />
    <limit
      lower="-2.27"
      upper="2.27"
      effort="100"
      velocity="1" />
  </joint>
  <link
    name="link7_left">
    <inertial>
      <origin
        xyz="0.000166942107998391 -0.0396172629342348 0.012470890893248"
        rpy="0 0 0" />
      <mass
        value="0.0255901502803906" />
      <inertia
        ixx="1.09563241253275E-05"
        ixy="7.44254767434469E-08"
        ixz="7.89954596848984E-10"
        iyy="6.66936792078847E-06"
        iyz="3.40119191817114E-07"
        izz="1.63416593378716E-05" />
    </inertial>
    <visual>
      <origin
        xyz="0 0 0"
        rpy="0 0 0" />
      <geometry>
        <mesh
          filename="package://stararm102_description/meshes/link7_left.STL" />
      </geometry>
      <material
        name="">
        <color
          rgba="1 1 1 1" />
      </material>
    </visual>
    <collision>
      <origin
        xyz="0 0 0"
        rpy="0 0 0" />
      <geometry>
        <mesh
          filename="package://stararm102_description/meshes/link7_left.STL" />
      </geometry>
    </collision>
  </link>
  <joint
    name="joint7_left"
    type="prismatic">
    <origin
      xyz="0 0.00090027 0"
      rpy="1.5708 0 -1.5708" />
    <parent
      link="link6" />
    <child
      link="link7_left" />
    <axis
      xyz="0 0 1" />
    <limit
      lower="0"
      upper="0.025"
      effort="5"
      velocity="3.14" />
  </joint>
  <link
    name="link7_right">
    <inertial>
      <origin
        xyz="0.000247064270466085 -0.0382132639534428 -0.00983566877683726"
        rpy="0 0 0" />
      <mass
        value="0.0246485351672712" />
      <inertia
        ixx="9.86971440894811E-06"
        ixy="1.28428957867994E-07"
        ixz="-8.80778532977007E-10"
        iyy="5.87737058201296E-06"
        iyz="-3.7706601751617E-07"
        izz="1.44729317459416E-05" />
    </inertial>
    <visual>
      <origin
        xyz="0 0 0"
        rpy="0 0 0" />
      <geometry>
        <mesh
          filename="package://stararm102_description/meshes/link7_right.STL" />
      </geometry>
      <material
        name="">
        <color
          rgba="1 1 1 1" />
      </material>
    </visual>
    <collision>
      <origin
        xyz="0 0 0"
        rpy="0 0 0" />
      <geometry>
        <mesh
          filename="package://stararm102_description/meshes/link7_right.STL" />
      </geometry>
    </collision>
  </link>
  <joint
    name="joint7_right"
    type="prismatic">
    <origin
      xyz="0 0.00090027 0"
      rpy="1.5708 0 -1.5708" />
    <parent
      link="link6" />
    <child
      link="link7_right" />
    <axis
      xyz="0 0 -1" />
    <limit
      lower="-0.025"
      upper="0"
      effort="5"
      velocity="3.14" />
    <mimic joint="joint7_left" />
  </joint>
</robot>